fn main() {
    let arr: [i32] = [1, 2, 3]
    
    try {
        let val = arr[3]
        print("ERROR: Should not reach here")
    } catch error {
        print("âœ… Caught expected error: {}", error)
    }
}